<?xml version="1.0"?>

<!--
Easily visualize / debug this URDF file on this site:
http://mymodelrobot.appspot.com/
-->

<robot name="quad">
  <link name="world"/>

  <link name="chassis_x">
  </link>

  <link name="chassis_z">
  </link>

  <link name="chassis_r">
    <visual>
      <geometry>
        <box size=".5 .5 .1"/>
      </geometry>
    </visual>
  </link>

  <joint name="x" type="prismatic">
    <parent link="world"/>
    <child link="chassis_x"/>
    <origin xyz="0 0 0" rpy="0 0 0" />
    <axis xyz="1 0 0"/>
    <limit effort="1000.0" lower="-5" upper="5" velocity="0.5"/>
  </joint>

  <joint name="z" type="prismatic">
    <parent link="chassis_x"/>
    <child link="chassis_z"/>
    <origin xyz="0 0 0" rpy="0 0 0" />
    <axis xyz="0 0 1"/>
    <limit effort="1000.0" lower="0" upper="10" velocity="0.5"/>
  </joint>

  <joint name="r" type="revolute">
    <parent link="chassis_z"/>
    <child link="chassis_r"/>
    <origin xyz="0 0 0" rpy="0 0 0" />
    <axis xyz="0 1 0"/>
    <limit effort="1000.0" lower="-3.14" upper="3.14" velocity="0.5"/>
  </joint>
</robot> 
